ERROR 2024-06-17 21:39:43,313 log Internal Server Error: /api/paraphrase
ERROR 2024-06-17 21:39:43,315 basehttp "POST /api/paraphrase HTTP/1.1" 500 43
ERROR 2024-06-17 21:39:50,490 log Internal Server Error: /api/paraphrase
ERROR 2024-06-17 21:39:50,494 basehttp "POST /api/paraphrase HTTP/1.1" 500 43
ERROR 2024-06-17 22:00:21,019 log Internal Server Error: /api/paraphrase
ERROR 2024-06-17 22:00:21,022 basehttp "POST /api/paraphrase HTTP/1.1" 500 43
ERROR 2024-06-18 11:41:10,655 log Internal Server Error: /api/paraphrase
ERROR 2024-06-18 11:41:10,655 basehttp "POST /api/paraphrase HTTP/1.1" 500 43
ERROR 2024-06-23 16:37:55,897 log Internal Server Error: /
Traceback (most recent call last):
  File "C:\Users\Nashit Budhwani\Downloads\AssignmentSolver-main\AssignmentSolver-main\backend\myenv\Lib\site-packages\django\core\handlers\exception.py", line 55, in inner
    response = get_response(request)
               ^^^^^^^^^^^^^^^^^^^^^
  File "C:\Users\Nashit Budhwani\Downloads\AssignmentSolver-main\AssignmentSolver-main\backend\myenv\Lib\site-packages\django\core\handlers\base.py", line 220, in _get_response
    response = response.render()
               ^^^^^^^^^^^^^^^^^
  File "C:\Users\Nashit Budhwani\Downloads\AssignmentSolver-main\AssignmentSolver-main\backend\myenv\Lib\site-packages\django\template\response.py", line 114, in render
    self.content = self.rendered_content
                   ^^^^^^^^^^^^^^^^^^^^^
  File "C:\Users\Nashit Budhwani\Downloads\AssignmentSolver-main\AssignmentSolver-main\backend\myenv\Lib\site-packages\django\template\response.py", line 90, in rendered_content
    template = self.resolve_template(self.template_name)
               ^^^^^^^^^^^^^^^^^^^^^^^^^^^^^^^^^^^^^^^^^
  File "C:\Users\Nashit Budhwani\Downloads\AssignmentSolver-main\AssignmentSolver-main\backend\myenv\Lib\site-packages\django\template\response.py", line 72, in resolve_template
    return select_template(template, using=self.using)
           ^^^^^^^^^^^^^^^^^^^^^^^^^^^^^^^^^^^^^^^^^^^
  File "C:\Users\Nashit Budhwani\Downloads\AssignmentSolver-main\AssignmentSolver-main\backend\myenv\Lib\site-packages\django\template\loader.py", line 47, in select_template
    raise TemplateDoesNotExist(", ".join(template_name_list), chain=chain)
django.template.exceptions.TemplateDoesNotExist: index.html
ERROR 2024-06-23 16:37:55,907 basehttp "GET / HTTP/1.1" 500 85446
ERROR 2024-06-23 16:38:22,264 log Internal Server Error: /
Traceback (most recent call last):
  File "C:\Users\Nashit Budhwani\Downloads\AssignmentSolver-main\AssignmentSolver-main\backend\myenv\Lib\site-packages\django\core\handlers\exception.py", line 55, in inner
    response = get_response(request)
               ^^^^^^^^^^^^^^^^^^^^^
  File "C:\Users\Nashit Budhwani\Downloads\AssignmentSolver-main\AssignmentSolver-main\backend\myenv\Lib\site-packages\django\core\handlers\base.py", line 220, in _get_response
    response = response.render()
               ^^^^^^^^^^^^^^^^^
  File "C:\Users\Nashit Budhwani\Downloads\AssignmentSolver-main\AssignmentSolver-main\backend\myenv\Lib\site-packages\django\template\response.py", line 114, in render
    self.content = self.rendered_content
                   ^^^^^^^^^^^^^^^^^^^^^
  File "C:\Users\Nashit Budhwani\Downloads\AssignmentSolver-main\AssignmentSolver-main\backend\myenv\Lib\site-packages\django\template\response.py", line 90, in rendered_content
    template = self.resolve_template(self.template_name)
               ^^^^^^^^^^^^^^^^^^^^^^^^^^^^^^^^^^^^^^^^^
  File "C:\Users\Nashit Budhwani\Downloads\AssignmentSolver-main\AssignmentSolver-main\backend\myenv\Lib\site-packages\django\template\response.py", line 72, in resolve_template
    return select_template(template, using=self.using)
           ^^^^^^^^^^^^^^^^^^^^^^^^^^^^^^^^^^^^^^^^^^^
  File "C:\Users\Nashit Budhwani\Downloads\AssignmentSolver-main\AssignmentSolver-main\backend\myenv\Lib\site-packages\django\template\loader.py", line 47, in select_template
    raise TemplateDoesNotExist(", ".join(template_name_list), chain=chain)
django.template.exceptions.TemplateDoesNotExist: index.html
ERROR 2024-06-23 16:38:22,272 basehttp "GET / HTTP/1.1" 500 85446
ERROR 2024-06-23 16:52:21,683 log Internal Server Error: /
Traceback (most recent call last):
  File "C:\Users\Nashit Budhwani\Downloads\AssignmentSolver-main\AssignmentSolver-main\backend\myenv\Lib\site-packages\django\core\handlers\exception.py", line 55, in inner
    response = get_response(request)
               ^^^^^^^^^^^^^^^^^^^^^
  File "C:\Users\Nashit Budhwani\Downloads\AssignmentSolver-main\AssignmentSolver-main\backend\myenv\Lib\site-packages\django\core\handlers\base.py", line 220, in _get_response
    response = response.render()
               ^^^^^^^^^^^^^^^^^
  File "C:\Users\Nashit Budhwani\Downloads\AssignmentSolver-main\AssignmentSolver-main\backend\myenv\Lib\site-packages\django\template\response.py", line 114, in render
    self.content = self.rendered_content
                   ^^^^^^^^^^^^^^^^^^^^^
  File "C:\Users\Nashit Budhwani\Downloads\AssignmentSolver-main\AssignmentSolver-main\backend\myenv\Lib\site-packages\django\template\response.py", line 90, in rendered_content
    template = self.resolve_template(self.template_name)
               ^^^^^^^^^^^^^^^^^^^^^^^^^^^^^^^^^^^^^^^^^
  File "C:\Users\Nashit Budhwani\Downloads\AssignmentSolver-main\AssignmentSolver-main\backend\myenv\Lib\site-packages\django\template\response.py", line 72, in resolve_template
    return select_template(template, using=self.using)
           ^^^^^^^^^^^^^^^^^^^^^^^^^^^^^^^^^^^^^^^^^^^
  File "C:\Users\Nashit Budhwani\Downloads\AssignmentSolver-main\AssignmentSolver-main\backend\myenv\Lib\site-packages\django\template\loader.py", line 47, in select_template
    raise TemplateDoesNotExist(", ".join(template_name_list), chain=chain)
django.template.exceptions.TemplateDoesNotExist: index.html
ERROR 2024-06-23 16:52:21,693 basehttp "GET / HTTP/1.1" 500 85622
ERROR 2024-06-23 16:56:22,530 log Internal Server Error: /api/paraphrase
ERROR 2024-06-23 16:56:22,530 basehttp "POST /api/paraphrase HTTP/1.1" 500 43
ERROR 2024-06-23 16:56:28,325 log Internal Server Error: /api/paraphrase
ERROR 2024-06-23 16:56:28,331 basehttp "POST /api/paraphrase HTTP/1.1" 500 43
ERROR 2024-06-23 17:06:37,281 log Internal Server Error: /
Traceback (most recent call last):
  File "C:\Users\Nashit Budhwani\Downloads\AssignmentSolver-main\AssignmentSolver-main\backend\myenv\Lib\site-packages\django\core\handlers\exception.py", line 55, in inner
    response = get_response(request)
               ^^^^^^^^^^^^^^^^^^^^^
  File "C:\Users\Nashit Budhwani\Downloads\AssignmentSolver-main\AssignmentSolver-main\backend\myenv\Lib\site-packages\django\core\handlers\base.py", line 220, in _get_response
    response = response.render()
               ^^^^^^^^^^^^^^^^^
  File "C:\Users\Nashit Budhwani\Downloads\AssignmentSolver-main\AssignmentSolver-main\backend\myenv\Lib\site-packages\django\template\response.py", line 114, in render
    self.content = self.rendered_content
                   ^^^^^^^^^^^^^^^^^^^^^
  File "C:\Users\Nashit Budhwani\Downloads\AssignmentSolver-main\AssignmentSolver-main\backend\myenv\Lib\site-packages\django\template\response.py", line 90, in rendered_content
    template = self.resolve_template(self.template_name)
               ^^^^^^^^^^^^^^^^^^^^^^^^^^^^^^^^^^^^^^^^^
  File "C:\Users\Nashit Budhwani\Downloads\AssignmentSolver-main\AssignmentSolver-main\backend\myenv\Lib\site-packages\django\template\response.py", line 72, in resolve_template
    return select_template(template, using=self.using)
           ^^^^^^^^^^^^^^^^^^^^^^^^^^^^^^^^^^^^^^^^^^^
  File "C:\Users\Nashit Budhwani\Downloads\AssignmentSolver-main\AssignmentSolver-main\backend\myenv\Lib\site-packages\django\template\loader.py", line 47, in select_template
    raise TemplateDoesNotExist(", ".join(template_name_list), chain=chain)
django.template.exceptions.TemplateDoesNotExist: index.html
ERROR 2024-06-23 17:06:37,308 basehttp "GET / HTTP/1.1" 500 85387
ERROR 2024-06-23 17:15:07,012 log Internal Server Error: /api/gpt
Traceback (most recent call last):
  File "C:\Users\Nashit Budhwani\Downloads\AssignmentSolver-main\AssignmentSolver-main\backend\myenv\Lib\site-packages\urllib3\connection.py", line 203, in _new_conn
    sock = connection.create_connection(
           ^^^^^^^^^^^^^^^^^^^^^^^^^^^^^
  File "C:\Users\Nashit Budhwani\Downloads\AssignmentSolver-main\AssignmentSolver-main\backend\myenv\Lib\site-packages\urllib3\util\connection.py", line 60, in create_connection
    for res in socket.getaddrinfo(host, port, family, socket.SOCK_STREAM):
               ^^^^^^^^^^^^^^^^^^^^^^^^^^^^^^^^^^^^^^^^^^^^^^^^^^^^^^^^^^
  File "C:\Python311\Lib\socket.py", line 962, in getaddrinfo
    for res in _socket.getaddrinfo(host, port, family, type, proto, flags):
               ^^^^^^^^^^^^^^^^^^^^^^^^^^^^^^^^^^^^^^^^^^^^^^^^^^^^^^^^^^^
socket.gaierror: [Errno 11002] getaddrinfo failed

The above exception was the direct cause of the following exception:

Traceback (most recent call last):
  File "C:\Users\Nashit Budhwani\Downloads\AssignmentSolver-main\AssignmentSolver-main\backend\myenv\Lib\site-packages\urllib3\connectionpool.py", line 790, in urlopen
    response = self._make_request(
               ^^^^^^^^^^^^^^^^^^^
  File "C:\Users\Nashit Budhwani\Downloads\AssignmentSolver-main\AssignmentSolver-main\backend\myenv\Lib\site-packages\urllib3\connectionpool.py", line 491, in _make_request
    raise new_e
  File "C:\Users\Nashit Budhwani\Downloads\AssignmentSolver-main\AssignmentSolver-main\backend\myenv\Lib\site-packages\urllib3\connectionpool.py", line 467, in _make_request
    self._validate_conn(conn)
  File "C:\Users\Nashit Budhwani\Downloads\AssignmentSolver-main\AssignmentSolver-main\backend\myenv\Lib\site-packages\urllib3\connectionpool.py", line 1096, in _validate_conn
    conn.connect()
  File "C:\Users\Nashit Budhwani\Downloads\AssignmentSolver-main\AssignmentSolver-main\backend\myenv\Lib\site-packages\urllib3\connection.py", line 611, in connect
    self.sock = sock = self._new_conn()
                       ^^^^^^^^^^^^^^^^
  File "C:\Users\Nashit Budhwani\Downloads\AssignmentSolver-main\AssignmentSolver-main\backend\myenv\Lib\site-packages\urllib3\connection.py", line 210, in _new_conn
    raise NameResolutionError(self.host, self, e) from e
urllib3.exceptions.NameResolutionError: <urllib3.connection.HTTPSConnection object at 0x000001F62F119F90>: Failed to resolve 'api-inference.huggingface.co' ([Errno 11002] getaddrinfo failed)

The above exception was the direct cause of the following exception:

Traceback (most recent call last):
  File "C:\Users\Nashit Budhwani\Downloads\AssignmentSolver-main\AssignmentSolver-main\backend\myenv\Lib\site-packages\requests\adapters.py", line 486, in send
    resp = conn.urlopen(
           ^^^^^^^^^^^^^
  File "C:\Users\Nashit Budhwani\Downloads\AssignmentSolver-main\AssignmentSolver-main\backend\myenv\Lib\site-packages\urllib3\connectionpool.py", line 844, in urlopen
    retries = retries.increment(
              ^^^^^^^^^^^^^^^^^^
  File "C:\Users\Nashit Budhwani\Downloads\AssignmentSolver-main\AssignmentSolver-main\backend\myenv\Lib\site-packages\urllib3\util\retry.py", line 515, in increment
    raise MaxRetryError(_pool, url, reason) from reason  # type: ignore[arg-type]
    ^^^^^^^^^^^^^^^^^^^^^^^^^^^^^^^^^^^^^^^^^^^^^^^^^^^
urllib3.exceptions.MaxRetryError: HTTPSConnectionPool(host='api-inference.huggingface.co', port=443): Max retries exceeded with url: /models/meta-llama/Meta-Llama-3-8B-Instruct (Caused by NameResolutionError("<urllib3.connection.HTTPSConnection object at 0x000001F62F119F90>: Failed to resolve 'api-inference.huggingface.co' ([Errno 11002] getaddrinfo failed)"))

During handling of the above exception, another exception occurred:

Traceback (most recent call last):
  File "C:\Users\Nashit Budhwani\Downloads\AssignmentSolver-main\AssignmentSolver-main\backend\myenv\Lib\site-packages\django\core\handlers\exception.py", line 55, in inner
    response = get_response(request)
               ^^^^^^^^^^^^^^^^^^^^^
  File "C:\Users\Nashit Budhwani\Downloads\AssignmentSolver-main\AssignmentSolver-main\backend\myenv\Lib\site-packages\django\core\handlers\base.py", line 197, in _get_response
    response = wrapped_callback(request, *callback_args, **callback_kwargs)
               ^^^^^^^^^^^^^^^^^^^^^^^^^^^^^^^^^^^^^^^^^^^^^^^^^^^^^^^^^^^^
  File "C:\Users\Nashit Budhwani\Downloads\AssignmentSolver-main\AssignmentSolver-main\backend\myenv\Lib\site-packages\django\views\decorators\csrf.py", line 65, in _view_wrapper
    return view_func(request, *args, **kwargs)
           ^^^^^^^^^^^^^^^^^^^^^^^^^^^^^^^^^^^
  File "C:\Users\Nashit Budhwani\Downloads\AssignmentSolver-main\AssignmentSolver-main\backend\myenv\Lib\site-packages\django\views\generic\base.py", line 104, in view
    return self.dispatch(request, *args, **kwargs)
           ^^^^^^^^^^^^^^^^^^^^^^^^^^^^^^^^^^^^^^^
  File "C:\Users\Nashit Budhwani\Downloads\AssignmentSolver-main\AssignmentSolver-main\backend\myenv\Lib\site-packages\rest_framework\views.py", line 509, in dispatch
    response = self.handle_exception(exc)
               ^^^^^^^^^^^^^^^^^^^^^^^^^^
  File "C:\Users\Nashit Budhwani\Downloads\AssignmentSolver-main\AssignmentSolver-main\backend\myenv\Lib\site-packages\rest_framework\views.py", line 469, in handle_exception
    self.raise_uncaught_exception(exc)
  File "C:\Users\Nashit Budhwani\Downloads\AssignmentSolver-main\AssignmentSolver-main\backend\myenv\Lib\site-packages\rest_framework\views.py", line 480, in raise_uncaught_exception
    raise exc
  File "C:\Users\Nashit Budhwani\Downloads\AssignmentSolver-main\AssignmentSolver-main\backend\myenv\Lib\site-packages\rest_framework\views.py", line 506, in dispatch
    response = handler(request, *args, **kwargs)
               ^^^^^^^^^^^^^^^^^^^^^^^^^^^^^^^^^
  File "C:\Users\Nashit Budhwani\Downloads\AssignmentSolver-main\AssignmentSolver-main\backend\gpt\views.py", line 19, in post
    output = query({
             ^^^^^^^
  File "C:\Users\Nashit Budhwani\Downloads\AssignmentSolver-main\AssignmentSolver-main\backend\gpt\utils.py", line 8, in query
    response = requests.post(API_URL, headers=headers, json=payload)
               ^^^^^^^^^^^^^^^^^^^^^^^^^^^^^^^^^^^^^^^^^^^^^^^^^^^^^
  File "C:\Users\Nashit Budhwani\Downloads\AssignmentSolver-main\AssignmentSolver-main\backend\myenv\Lib\site-packages\requests\api.py", line 115, in post
    return request("post", url, data=data, json=json, **kwargs)
           ^^^^^^^^^^^^^^^^^^^^^^^^^^^^^^^^^^^^^^^^^^^^^^^^^^^^
  File "C:\Users\Nashit Budhwani\Downloads\AssignmentSolver-main\AssignmentSolver-main\backend\myenv\Lib\site-packages\requests\api.py", line 59, in request
    return session.request(method=method, url=url, **kwargs)
           ^^^^^^^^^^^^^^^^^^^^^^^^^^^^^^^^^^^^^^^^^^^^^^^^^
  File "C:\Users\Nashit Budhwani\Downloads\AssignmentSolver-main\AssignmentSolver-main\backend\myenv\Lib\site-packages\requests\sessions.py", line 589, in request
    resp = self.send(prep, **send_kwargs)
           ^^^^^^^^^^^^^^^^^^^^^^^^^^^^^^
  File "C:\Users\Nashit Budhwani\Downloads\AssignmentSolver-main\AssignmentSolver-main\backend\myenv\Lib\site-packages\requests\sessions.py", line 703, in send
    r = adapter.send(request, **kwargs)
        ^^^^^^^^^^^^^^^^^^^^^^^^^^^^^^^
  File "C:\Users\Nashit Budhwani\Downloads\AssignmentSolver-main\AssignmentSolver-main\backend\myenv\Lib\site-packages\requests\adapters.py", line 519, in send
    raise ConnectionError(e, request=request)
requests.exceptions.ConnectionError: HTTPSConnectionPool(host='api-inference.huggingface.co', port=443): Max retries exceeded with url: /models/meta-llama/Meta-Llama-3-8B-Instruct (Caused by NameResolutionError("<urllib3.connection.HTTPSConnection object at 0x000001F62F119F90>: Failed to resolve 'api-inference.huggingface.co' ([Errno 11002] getaddrinfo failed)"))
ERROR 2024-06-23 17:15:07,071 basehttp "POST /api/gpt HTTP/1.1" 500 243389
ERROR 2024-06-23 17:16:06,590 log Internal Server Error: /api/gpt
Traceback (most recent call last):
  File "C:\Users\Nashit Budhwani\Downloads\AssignmentSolver-main\AssignmentSolver-main\backend\myenv\Lib\site-packages\urllib3\connection.py", line 203, in _new_conn
    sock = connection.create_connection(
           ^^^^^^^^^^^^^^^^^^^^^^^^^^^^^
  File "C:\Users\Nashit Budhwani\Downloads\AssignmentSolver-main\AssignmentSolver-main\backend\myenv\Lib\site-packages\urllib3\util\connection.py", line 60, in create_connection
    for res in socket.getaddrinfo(host, port, family, socket.SOCK_STREAM):
               ^^^^^^^^^^^^^^^^^^^^^^^^^^^^^^^^^^^^^^^^^^^^^^^^^^^^^^^^^^
  File "C:\Python311\Lib\socket.py", line 962, in getaddrinfo
    for res in _socket.getaddrinfo(host, port, family, type, proto, flags):
               ^^^^^^^^^^^^^^^^^^^^^^^^^^^^^^^^^^^^^^^^^^^^^^^^^^^^^^^^^^^
socket.gaierror: [Errno 11002] getaddrinfo failed

The above exception was the direct cause of the following exception:

Traceback (most recent call last):
  File "C:\Users\Nashit Budhwani\Downloads\AssignmentSolver-main\AssignmentSolver-main\backend\myenv\Lib\site-packages\urllib3\connectionpool.py", line 790, in urlopen
    response = self._make_request(
               ^^^^^^^^^^^^^^^^^^^
  File "C:\Users\Nashit Budhwani\Downloads\AssignmentSolver-main\AssignmentSolver-main\backend\myenv\Lib\site-packages\urllib3\connectionpool.py", line 491, in _make_request
    raise new_e
  File "C:\Users\Nashit Budhwani\Downloads\AssignmentSolver-main\AssignmentSolver-main\backend\myenv\Lib\site-packages\urllib3\connectionpool.py", line 467, in _make_request
    self._validate_conn(conn)
  File "C:\Users\Nashit Budhwani\Downloads\AssignmentSolver-main\AssignmentSolver-main\backend\myenv\Lib\site-packages\urllib3\connectionpool.py", line 1096, in _validate_conn
    conn.connect()
  File "C:\Users\Nashit Budhwani\Downloads\AssignmentSolver-main\AssignmentSolver-main\backend\myenv\Lib\site-packages\urllib3\connection.py", line 611, in connect
    self.sock = sock = self._new_conn()
                       ^^^^^^^^^^^^^^^^
  File "C:\Users\Nashit Budhwani\Downloads\AssignmentSolver-main\AssignmentSolver-main\backend\myenv\Lib\site-packages\urllib3\connection.py", line 210, in _new_conn
    raise NameResolutionError(self.host, self, e) from e
urllib3.exceptions.NameResolutionError: <urllib3.connection.HTTPSConnection object at 0x000001F62F070890>: Failed to resolve 'api-inference.huggingface.co' ([Errno 11002] getaddrinfo failed)

The above exception was the direct cause of the following exception:

Traceback (most recent call last):
  File "C:\Users\Nashit Budhwani\Downloads\AssignmentSolver-main\AssignmentSolver-main\backend\myenv\Lib\site-packages\requests\adapters.py", line 486, in send
    resp = conn.urlopen(
           ^^^^^^^^^^^^^
  File "C:\Users\Nashit Budhwani\Downloads\AssignmentSolver-main\AssignmentSolver-main\backend\myenv\Lib\site-packages\urllib3\connectionpool.py", line 844, in urlopen
    retries = retries.increment(
              ^^^^^^^^^^^^^^^^^^
  File "C:\Users\Nashit Budhwani\Downloads\AssignmentSolver-main\AssignmentSolver-main\backend\myenv\Lib\site-packages\urllib3\util\retry.py", line 515, in increment
    raise MaxRetryError(_pool, url, reason) from reason  # type: ignore[arg-type]
    ^^^^^^^^^^^^^^^^^^^^^^^^^^^^^^^^^^^^^^^^^^^^^^^^^^^
urllib3.exceptions.MaxRetryError: HTTPSConnectionPool(host='api-inference.huggingface.co', port=443): Max retries exceeded with url: /models/meta-llama/Meta-Llama-3-8B-Instruct (Caused by NameResolutionError("<urllib3.connection.HTTPSConnection object at 0x000001F62F070890>: Failed to resolve 'api-inference.huggingface.co' ([Errno 11002] getaddrinfo failed)"))

During handling of the above exception, another exception occurred:

Traceback (most recent call last):
  File "C:\Users\Nashit Budhwani\Downloads\AssignmentSolver-main\AssignmentSolver-main\backend\myenv\Lib\site-packages\django\core\handlers\exception.py", line 55, in inner
    response = get_response(request)
               ^^^^^^^^^^^^^^^^^^^^^
  File "C:\Users\Nashit Budhwani\Downloads\AssignmentSolver-main\AssignmentSolver-main\backend\myenv\Lib\site-packages\django\core\handlers\base.py", line 197, in _get_response
    response = wrapped_callback(request, *callback_args, **callback_kwargs)
               ^^^^^^^^^^^^^^^^^^^^^^^^^^^^^^^^^^^^^^^^^^^^^^^^^^^^^^^^^^^^
  File "C:\Users\Nashit Budhwani\Downloads\AssignmentSolver-main\AssignmentSolver-main\backend\myenv\Lib\site-packages\django\views\decorators\csrf.py", line 65, in _view_wrapper
    return view_func(request, *args, **kwargs)
           ^^^^^^^^^^^^^^^^^^^^^^^^^^^^^^^^^^^
  File "C:\Users\Nashit Budhwani\Downloads\AssignmentSolver-main\AssignmentSolver-main\backend\myenv\Lib\site-packages\django\views\generic\base.py", line 104, in view
    return self.dispatch(request, *args, **kwargs)
           ^^^^^^^^^^^^^^^^^^^^^^^^^^^^^^^^^^^^^^^
  File "C:\Users\Nashit Budhwani\Downloads\AssignmentSolver-main\AssignmentSolver-main\backend\myenv\Lib\site-packages\rest_framework\views.py", line 509, in dispatch
    response = self.handle_exception(exc)
               ^^^^^^^^^^^^^^^^^^^^^^^^^^
  File "C:\Users\Nashit Budhwani\Downloads\AssignmentSolver-main\AssignmentSolver-main\backend\myenv\Lib\site-packages\rest_framework\views.py", line 469, in handle_exception
    self.raise_uncaught_exception(exc)
  File "C:\Users\Nashit Budhwani\Downloads\AssignmentSolver-main\AssignmentSolver-main\backend\myenv\Lib\site-packages\rest_framework\views.py", line 480, in raise_uncaught_exception
    raise exc
  File "C:\Users\Nashit Budhwani\Downloads\AssignmentSolver-main\AssignmentSolver-main\backend\myenv\Lib\site-packages\rest_framework\views.py", line 506, in dispatch
    response = handler(request, *args, **kwargs)
               ^^^^^^^^^^^^^^^^^^^^^^^^^^^^^^^^^
  File "C:\Users\Nashit Budhwani\Downloads\AssignmentSolver-main\AssignmentSolver-main\backend\gpt\views.py", line 19, in post
    output = query({
             ^^^^^^^
  File "C:\Users\Nashit Budhwani\Downloads\AssignmentSolver-main\AssignmentSolver-main\backend\gpt\utils.py", line 8, in query
    response = requests.post(API_URL, headers=headers, json=payload)
               ^^^^^^^^^^^^^^^^^^^^^^^^^^^^^^^^^^^^^^^^^^^^^^^^^^^^^
  File "C:\Users\Nashit Budhwani\Downloads\AssignmentSolver-main\AssignmentSolver-main\backend\myenv\Lib\site-packages\requests\api.py", line 115, in post
    return request("post", url, data=data, json=json, **kwargs)
           ^^^^^^^^^^^^^^^^^^^^^^^^^^^^^^^^^^^^^^^^^^^^^^^^^^^^
  File "C:\Users\Nashit Budhwani\Downloads\AssignmentSolver-main\AssignmentSolver-main\backend\myenv\Lib\site-packages\requests\api.py", line 59, in request
    return session.request(method=method, url=url, **kwargs)
           ^^^^^^^^^^^^^^^^^^^^^^^^^^^^^^^^^^^^^^^^^^^^^^^^^
  File "C:\Users\Nashit Budhwani\Downloads\AssignmentSolver-main\AssignmentSolver-main\backend\myenv\Lib\site-packages\requests\sessions.py", line 589, in request
    resp = self.send(prep, **send_kwargs)
           ^^^^^^^^^^^^^^^^^^^^^^^^^^^^^^
  File "C:\Users\Nashit Budhwani\Downloads\AssignmentSolver-main\AssignmentSolver-main\backend\myenv\Lib\site-packages\requests\sessions.py", line 703, in send
    r = adapter.send(request, **kwargs)
        ^^^^^^^^^^^^^^^^^^^^^^^^^^^^^^^
  File "C:\Users\Nashit Budhwani\Downloads\AssignmentSolver-main\AssignmentSolver-main\backend\myenv\Lib\site-packages\requests\adapters.py", line 519, in send
    raise ConnectionError(e, request=request)
requests.exceptions.ConnectionError: HTTPSConnectionPool(host='api-inference.huggingface.co', port=443): Max retries exceeded with url: /models/meta-llama/Meta-Llama-3-8B-Instruct (Caused by NameResolutionError("<urllib3.connection.HTTPSConnection object at 0x000001F62F070890>: Failed to resolve 'api-inference.huggingface.co' ([Errno 11002] getaddrinfo failed)"))
ERROR 2024-06-23 17:16:06,638 basehttp "POST /api/gpt HTTP/1.1" 500 245050
ERROR 2024-06-23 17:16:34,088 log Internal Server Error: /api/paraphrase
ERROR 2024-06-23 17:16:34,088 basehttp "POST /api/paraphrase HTTP/1.1" 500 43
